2018-06-14 17:07:13,393 INFO: Microblog startup [in /home/duan/Flask_microblog/app/__init__.py:49]
2018-06-14 17:16:58,104 INFO: Microblog startup [in /home/duan/Flask_microblog/app/__init__.py:49]
2018-06-14 17:17:07,182 ERROR: Exception on /logout [GET] [in /home/duan/.local/share/virtualenvs/Flask_microblog-6CoWjSse/lib/python3.6/site-packages/flask/app.py:1761]
Traceback (most recent call last):
  File "/home/duan/.local/share/virtualenvs/Flask_microblog-6CoWjSse/lib/python3.6/site-packages/flask/app.py", line 2292, in wsgi_app
    response = self.full_dispatch_request()
  File "/home/duan/.local/share/virtualenvs/Flask_microblog-6CoWjSse/lib/python3.6/site-packages/flask/app.py", line 1815, in full_dispatch_request
    rv = self.handle_user_exception(e)
  File "/home/duan/.local/share/virtualenvs/Flask_microblog-6CoWjSse/lib/python3.6/site-packages/flask/app.py", line 1718, in handle_user_exception
    reraise(exc_type, exc_value, tb)
  File "/home/duan/.local/share/virtualenvs/Flask_microblog-6CoWjSse/lib/python3.6/site-packages/flask/_compat.py", line 35, in reraise
    raise value
  File "/home/duan/.local/share/virtualenvs/Flask_microblog-6CoWjSse/lib/python3.6/site-packages/flask/app.py", line 1813, in full_dispatch_request
    rv = self.dispatch_request()
  File "/home/duan/.local/share/virtualenvs/Flask_microblog-6CoWjSse/lib/python3.6/site-packages/flask/app.py", line 1799, in dispatch_request
    return self.view_functions[rule.endpoint](**req.view_args)
  File "/home/duan/Flask_microblog/app/routes.py", line 72, in logout
    hhalogout_user()
NameError: name 'hhalogout_user' is not defined
2018-06-14 17:20:27,900 INFO: Microblog startup [in /home/duan/Flask_microblog/app/__init__.py:49]
2018-06-14 17:20:35,027 ERROR: Exception on /logout [GET] [in /home/duan/.local/share/virtualenvs/Flask_microblog-6CoWjSse/lib/python3.6/site-packages/flask/app.py:1761]
Traceback (most recent call last):
  File "/home/duan/.local/share/virtualenvs/Flask_microblog-6CoWjSse/lib/python3.6/site-packages/flask/app.py", line 2292, in wsgi_app
    response = self.full_dispatch_request()
  File "/home/duan/.local/share/virtualenvs/Flask_microblog-6CoWjSse/lib/python3.6/site-packages/flask/app.py", line 1815, in full_dispatch_request
    rv = self.handle_user_exception(e)
  File "/home/duan/.local/share/virtualenvs/Flask_microblog-6CoWjSse/lib/python3.6/site-packages/flask/app.py", line 1718, in handle_user_exception
    reraise(exc_type, exc_value, tb)
  File "/home/duan/.local/share/virtualenvs/Flask_microblog-6CoWjSse/lib/python3.6/site-packages/flask/_compat.py", line 35, in reraise
    raise value
  File "/home/duan/.local/share/virtualenvs/Flask_microblog-6CoWjSse/lib/python3.6/site-packages/flask/app.py", line 1813, in full_dispatch_request
    rv = self.dispatch_request()
  File "/home/duan/.local/share/virtualenvs/Flask_microblog-6CoWjSse/lib/python3.6/site-packages/flask/app.py", line 1799, in dispatch_request
    return self.view_functions[rule.endpoint](**req.view_args)
  File "/home/duan/Flask_microblog/app/routes.py", line 72, in logout
    hhalogout_user()
NameError: name 'hhalogout_user' is not defined
2018-06-14 17:22:18,467 ERROR: Exception on /logout [GET] [in /home/duan/.local/share/virtualenvs/Flask_microblog-6CoWjSse/lib/python3.6/site-packages/flask/app.py:1761]
Traceback (most recent call last):
  File "/home/duan/.local/share/virtualenvs/Flask_microblog-6CoWjSse/lib/python3.6/site-packages/flask/app.py", line 2292, in wsgi_app
    response = self.full_dispatch_request()
  File "/home/duan/.local/share/virtualenvs/Flask_microblog-6CoWjSse/lib/python3.6/site-packages/flask/app.py", line 1815, in full_dispatch_request
    rv = self.handle_user_exception(e)
  File "/home/duan/.local/share/virtualenvs/Flask_microblog-6CoWjSse/lib/python3.6/site-packages/flask/app.py", line 1718, in handle_user_exception
    reraise(exc_type, exc_value, tb)
  File "/home/duan/.local/share/virtualenvs/Flask_microblog-6CoWjSse/lib/python3.6/site-packages/flask/_compat.py", line 35, in reraise
    raise value
  File "/home/duan/.local/share/virtualenvs/Flask_microblog-6CoWjSse/lib/python3.6/site-packages/flask/app.py", line 1813, in full_dispatch_request
    rv = self.dispatch_request()
  File "/home/duan/.local/share/virtualenvs/Flask_microblog-6CoWjSse/lib/python3.6/site-packages/flask/app.py", line 1799, in dispatch_request
    return self.view_functions[rule.endpoint](**req.view_args)
  File "/home/duan/Flask_microblog/app/routes.py", line 72, in logout
    hhalogout_user()
NameError: name 'hhalogout_user' is not defined
2018-06-14 17:22:19,562 ERROR: Exception on /logout [GET] [in /home/duan/.local/share/virtualenvs/Flask_microblog-6CoWjSse/lib/python3.6/site-packages/flask/app.py:1761]
Traceback (most recent call last):
  File "/home/duan/.local/share/virtualenvs/Flask_microblog-6CoWjSse/lib/python3.6/site-packages/flask/app.py", line 2292, in wsgi_app
    response = self.full_dispatch_request()
  File "/home/duan/.local/share/virtualenvs/Flask_microblog-6CoWjSse/lib/python3.6/site-packages/flask/app.py", line 1815, in full_dispatch_request
    rv = self.handle_user_exception(e)
  File "/home/duan/.local/share/virtualenvs/Flask_microblog-6CoWjSse/lib/python3.6/site-packages/flask/app.py", line 1718, in handle_user_exception
    reraise(exc_type, exc_value, tb)
  File "/home/duan/.local/share/virtualenvs/Flask_microblog-6CoWjSse/lib/python3.6/site-packages/flask/_compat.py", line 35, in reraise
    raise value
  File "/home/duan/.local/share/virtualenvs/Flask_microblog-6CoWjSse/lib/python3.6/site-packages/flask/app.py", line 1813, in full_dispatch_request
    rv = self.dispatch_request()
  File "/home/duan/.local/share/virtualenvs/Flask_microblog-6CoWjSse/lib/python3.6/site-packages/flask/app.py", line 1799, in dispatch_request
    return self.view_functions[rule.endpoint](**req.view_args)
  File "/home/duan/Flask_microblog/app/routes.py", line 72, in logout
    hhalogout_user()
NameError: name 'hhalogout_user' is not defined
2018-06-14 17:22:22,609 ERROR: Exception on /logout [GET] [in /home/duan/.local/share/virtualenvs/Flask_microblog-6CoWjSse/lib/python3.6/site-packages/flask/app.py:1761]
Traceback (most recent call last):
  File "/home/duan/.local/share/virtualenvs/Flask_microblog-6CoWjSse/lib/python3.6/site-packages/flask/app.py", line 2292, in wsgi_app
    response = self.full_dispatch_request()
  File "/home/duan/.local/share/virtualenvs/Flask_microblog-6CoWjSse/lib/python3.6/site-packages/flask/app.py", line 1815, in full_dispatch_request
    rv = self.handle_user_exception(e)
  File "/home/duan/.local/share/virtualenvs/Flask_microblog-6CoWjSse/lib/python3.6/site-packages/flask/app.py", line 1718, in handle_user_exception
    reraise(exc_type, exc_value, tb)
  File "/home/duan/.local/share/virtualenvs/Flask_microblog-6CoWjSse/lib/python3.6/site-packages/flask/_compat.py", line 35, in reraise
    raise value
  File "/home/duan/.local/share/virtualenvs/Flask_microblog-6CoWjSse/lib/python3.6/site-packages/flask/app.py", line 1813, in full_dispatch_request
    rv = self.dispatch_request()
  File "/home/duan/.local/share/virtualenvs/Flask_microblog-6CoWjSse/lib/python3.6/site-packages/flask/app.py", line 1799, in dispatch_request
    return self.view_functions[rule.endpoint](**req.view_args)
  File "/home/duan/Flask_microblog/app/routes.py", line 72, in logout
    hhalogout_user()
NameError: name 'hhalogout_user' is not defined
2018-06-14 17:44:33,255 INFO: Microblog startup [in /home/duan/Flask_microblog/app/__init__.py:49]
2018-06-14 17:44:39,628 ERROR: Exception on /logout [GET] [in /home/duan/.local/share/virtualenvs/Flask_microblog-6CoWjSse/lib/python3.6/site-packages/flask/app.py:1761]
Traceback (most recent call last):
  File "/home/duan/.local/share/virtualenvs/Flask_microblog-6CoWjSse/lib/python3.6/site-packages/flask/app.py", line 2292, in wsgi_app
    response = self.full_dispatch_request()
  File "/home/duan/.local/share/virtualenvs/Flask_microblog-6CoWjSse/lib/python3.6/site-packages/flask/app.py", line 1815, in full_dispatch_request
    rv = self.handle_user_exception(e)
  File "/home/duan/.local/share/virtualenvs/Flask_microblog-6CoWjSse/lib/python3.6/site-packages/flask/app.py", line 1718, in handle_user_exception
    reraise(exc_type, exc_value, tb)
  File "/home/duan/.local/share/virtualenvs/Flask_microblog-6CoWjSse/lib/python3.6/site-packages/flask/_compat.py", line 35, in reraise
    raise value
  File "/home/duan/.local/share/virtualenvs/Flask_microblog-6CoWjSse/lib/python3.6/site-packages/flask/app.py", line 1813, in full_dispatch_request
    rv = self.dispatch_request()
  File "/home/duan/.local/share/virtualenvs/Flask_microblog-6CoWjSse/lib/python3.6/site-packages/flask/app.py", line 1799, in dispatch_request
    return self.view_functions[rule.endpoint](**req.view_args)
  File "/home/duan/Flask_microblog/app/routes.py", line 72, in logout
    hhalogout_user()
NameError: name 'hhalogout_user' is not defined
